Workbook

Sheet tax
A1: Sites | B1: Sites1 | C1: Acanthostracion polygonius | D1: Acanthurus bahianus | E1: Achirus lineatus | F1: Antennarius pauciradiatus | G1: Antennarius striatus | H1: Apogon aurolineatus | I1: Apogon pillionatus | J1: Apogon pseudomaculatus | K1: Apogon quadrisquamatus | L1: Astrapogon alutus | M1: Aulostomus maculatus | N1: Bollmannia boqueronensis | O1: Bothus lunatus | P1: Bothus ocellatus | Q1: Calamus pennatula | R1: Callionymus bairdi | S1: Chaetodon sedentarius | T1: Chilomycterus antillarum | U1: Chloroscombrus chrysurus | V1: Chromis insolata | W1: Dactylopterus volitans | X1: Diapterus rhombeus | Y1: Diodon holocanthus | Z1: Diplectrum bivittatum | AA1: Diplogrammus pauciradiatus | AB1: Eucinostomus argenteus | AC1: Eucinostomus gula | AD1: Fistularia tabacaria | AE1: Gymnothorax ocellatus | AF1: Haemulon aurolineatum | AG1: Halichoeres pictus | AH1: Halieutichthys aculeatus | AI1: Hippocampus erectus | AJ1: Holocentrus adscensionis | AK1: Lutjanus analis | AL1: Lutjanus synagris | AM1: Monacanthus ciliatus | AN1: Myripristis jacobus | AO1: Ogcocephalus parvus | AP1: Ogcocephalus pumilus | AQ1: Peprilus paru | AR1: Pontinus rathbuni | AS1: Priacanthus arenatus | AT1: Prionotus punctatus | AU1: Pristipomoides aquilonaris | AV1: Pronotogrammus martinicensis | AW1: Pseudupeneus maculatus | AX1: Rypticus bistrispinus | AY1: Saurida brasiliensis | AZ1: Saurida normani | BA1: Scorpaena albifimbria | BB1: Scorpaena bergii | BC1: Scorpaena calcarata | BD1: Scorpaena isthmensis | BE1: Serraniculus pumilio | BF1: Serranus atrobranchus | BG1: Serranus chionaraia | BH1: Serranus flaviventris | BI1: Serranus phoebe | BJ1: Serranus tortugarum | BK1: Sphoeroides dorsalis | BL1: Sphoeroides spengleri | BM1: Starksia nanodes | BN1: Stephanolepis setifer | BO1: Syacium micrurum | BP1: Syacium papillosum | BQ1: Symphurus diomedeanus | BR1: Synodus foetens | BS1: Synodus intermedius | BT1: Synodus poeyi | BU1: Synodus saurus | BV1: Synodus synodus | BW1: Thalassophryne maculosa | BX1: Trachinocephalus myops | BY1: Upeneus parvus
A2: E44 | B2: N | C2: 0 | D2: 0 | E2: 0 | F2: 0 | G2: 0 | H2: 0 | I2: 0 | J2: 0 | K2: 0 | L2: 0 | M2: 0 | N2: 0 | O2: 0 | P2: 0 | Q2: 0 | R2: 0 | S2: 0 | T2: 0 | U2: 20 | V2: 0 | W2: 0 | X2: 1 | Y2: 0 | Z2: 0 | AA2: 0 | AB2: 0 | AC2: 0 | AD2: 0 | AE2: 0 | AF2: 0 | AG2: 0 | AH2: 1 | AI2: 0 | AJ2: 0 | AK2: 0 | AL2: 0 | AM2: 0 | AN2: 0 | AO2: 0 | AP2: 0 | AQ2: 43 | AR2: 0 | AS2: 0 | AT2: 30 | AU2: 0 | AV2: 0 | AW2: 0 | AX2: 0 | AY2: 0 | AZ2: 0 | BA2: 0 | BB2: 1 | BC2: 0 | BD2: 0 | BE2: 0 | BF2: 2 | BG2: 0 | BH2: 0 | BI2: 0 | BJ2: 0 | BK2: 0 | BL2: 0 | BM2: 0 | BN2: 0 | BO2: 0 | BP2: 0 | BQ2: 0 | BR2: 0 | BS2: 0 | BT2: 0 | BU2: 0 | BV2: 0 | BW2: 0 | BX2: 0 | BY2: 0
A3: E45 | B3: N | C3: 0 | D3: 0 | E3: 0 | F3: 0 | G3: 0 | H3: 0 | I3: 0 | J3: 8 | K3: 0 | L3: 0 | M3: 0 | N3: 0 | O3: 0 | P3: 1 | Q3: 0 | R3: 0 | S3: 0 | T3: 0 | U3: 0 | V3: 0 | W3: 0 | X3: 0 | Y3: 0 | Z3: 0 | AA3: 0 | AB3: 0 | AC3: 0 | AD3: 0 | AE3: 0 | AF3: 0 | AG3: 1 | AH3: 0 | AI3: 0 | AJ3: 0 | AK3: 1 | AL3: 0 | AM3: 0 | AN3: 0 | AO3: 0 | AP3: 0 | AQ3: 0 | AR3: 1 | AS3: 0 | AT3: 0 | AU3: 0 | AV3: 15 | AW3: 0 | AX3: 0 | AY3: 42 | AZ3: 0 | BA3: 0 | BB3: 0 | BC3: 0 | BD3: 0 | BE3: 0 | BF3: 25 | BG3: 4 | BH3: 0 | BI3: 0 | BJ3: 0 | BK3: 0 | BL3: 0 | BM3: 0 | BN3: 0 | BO3: 4 | BP3: 4 | BQ3: 0 | BR3: 0 | BS3: 0 | BT3: 0 | BU3: 0 | BV3: 0 | BW3: 4 | BX3: 0 | BY3: 2
A4: E48 | B4: N | C4: 0 | D4: 0 | E4: 0 | F4: 0 | G4: 1 | H4: 1 | I4: 0 | J4: 14 | K4: 7 | L4: 0 | M4: 0 | N4: 0 | O4: 0 | P4: 2 | Q4: 0 | R4: 0 | S4: 0 | T4: 0 | U4: 0 | V4: 0 | W4: 0 | X4: 0 | Y4: 0 | Z4: 10 | AA4: 0 | AB4: 0 | AC4: 0 | AD4: 0 | AE4: 0 | AF4: 4 | AG4: 0 | AH4: 1 | AI4: 1 | AJ4: 1 | AK4: 0 | AL4: 0 | AM4: 2 | AN4: 1 | AO4: 0 | AP4: 0 | AQ4: 0 | AR4: 0 | AS4: 0 | AT4: 0 | AU4: 1 | AV4: 0 | AW4: 0 | AX4: 0 | AY4: 0 | AZ4: 0 | BA4: 0 | BB4: 2 | BC4: 9 | BD4: 1 | BE4: 0 | BF4: 0 | BG4: 1 | BH4: 0 | BI4: 4 | BJ4: 0 | BK4: 0 | BL4: 0 | BM4: 1 | BN4: 1 | BO4: 0 | BP4: 0 | BQ4: 0 | BR4: 0 | BS4: 1 | BT4: 1 | BU4: 0 | BV4: 0 | BW4: 0 | BX4: 0 | BY4: 0
A5: E49 | B5: N | C5: 0 | D5: 0 | E5: 0 | F5: 0 | G5: 0 | H5: 0 | I5: 0 | J5: 0 | K5: 0 | L5: 0 | M5: 0 | N5: 1 | O5: 0 | P5: 7 | Q5: 0 | R5: 0 | S5: 0 | T5: 0 | U5: 0 | V5: 0 | W5: 0 | X5: 0 | Y5: 0 | Z5: 1 | AA5: 0 | AB5: 0 | AC5: 0 | AD5: 0 | AE5: 0 | AF5: 0 | AG5: 0 | AH5: 0 | AI5: 0 | AJ5: 0 | AK5: 0 | AL5: 0 | AM5: 0 | AN5: 0 | AO5: 0 | AP5: 1 | AQ5: 0 | AR5: 0 | AS5: 0 | AT5: 4 | AU5: 0 | AV5: 0 | AW5: 0 | AX5: 0 | AY5: 0 | AZ5: 0 | BA5: 0 | BB5: 0 | BC5: 0 | BD5: 0 | BE5: 0 | BF5: 0 | BG5: 0 | BH5: 0 | BI5: 0 | BJ5: 0 | BK5: 0 | BL5: 1 | BM5: 0 | BN5: 0 | BO5: 0 | BP5: 2 | BQ5: 0 | BR5: 0 | BS5: 0 | BT5: 0 | BU5: 2 | BV5: 0 | BW5: 0 | BX5: 2 | BY5: 0
A6: E51 | B6: N | C6: 0 | D6: 0 | E6: 0 | F6: 2 | G6: 0 | H6: 0 | I6: 0 | J6: 1 | K6: 2 | L6: 0 | M6: 0 | N6: 0 | O6: 0 | P6: 0 | Q6: 0 | R6: 1 | S6: 0 | T6: 0 | U6: 0 | V6: 0 | W6: 0 | X6: 0 | Y6: 0 | Z6: 0 | AA6: 0 | AB6: 0 | AC6: 0 | AD6: 0 | AE6: 0 | AF6: 0 | AG6: 0 | AH6: 1 | AI6: 0 | AJ6: 0 | AK6: 0 | AL6: 0 | AM6: 1 | AN6: 0 | AO6: 0 | AP6: 0 | AQ6: 0 | AR6: 0 | AS6: 1 | AT6: 0 | AU6: 0 | AV6: 1 | AW6: 0 | AX6: 0 | AY6: 23 | AZ6: 0 | BA6: 0 | BB6: 0 | BC6: 3 | BD6: 0 | BE6: 0 | BF6: 5 | BG6: 24 | BH6: 0 | BI6: 0 | BJ6: 1 | BK6: 0 | BL6: 0 | BM6: 0 | BN6: 0 | BO6: 2 | BP6: 0 | BQ6: 0 | BR6: 0 | BS6: 0 | BT6: 7 | BU6: 0 | BV6: 0 | BW6: 0 | BX6: 0 | BY6: 0
A7: E52 | B7: N | C7: 0 | D7: 0 | E7: 0 | F7: 0 | G7: 2 | H7: 0 | I7: 0 | J7: 0 | K7: 0 | L7: 0 | M7: 0 | N7: 0 | O7: 0 | P7: 0 | Q7: 0 | R7: 0 | S7: 0 | T7: 0 | U7: 7 | V7: 0 | W7: 0 | X7: 0 | Y7: 0 | Z7: 4 | AA7: 0 | AB7: 0 | AC7: 4 | AD7: 0 | AE7: 0 | AF7: 0 | AG7: 0 | AH7: 0 | AI7: 0 | AJ7: 0 | AK7: 0 | AL7: 3 | AM7: 0 | AN7: 0 | AO7: 0 | AP7: 0 | AQ7: 0 | AR7: 0 | AS7: 0 | AT7: 11 | AU7: 0 | AV7: 0 | AW7: 0 | AX7: 0 | AY7: 0 | AZ7: 0 | BA7: 0 | BB7: 0 | BC7: 0 | BD7: 0 | BE7: 0 | BF7: 5 | BG7: 0 | BH7: 0 | BI7: 0 | BJ7: 0 | BK7: 0 | BL7: 0 | BM7: 0 | BN7: 2 | BO7: 0 | BP7: 0 | BQ7: 0 | BR7: 3 | BS7: 0 | BT7: 2 | BU7: 0 | BV7: 0 | BW7: 0 | BX7: 0 | BY7: 7
A8: E53 | B8: N | C8: 0 | D8: 0 | E8: 0 | F8: 0 | G8: 1 | H8: 0 | I8: 0 | J8: 3 | K8: 13 | L8: 0 | M8: 0 | N8: 0 | O8: 0 | P8: 0 | Q8: 1 | R8: 0 | S8: 0 | T8: 0 | U8: 0 | V8: 0 | W8: 0 | X8: 0 | Y8: 0 | Z8: 3 | AA8: 0 | AB8: 0 | AC8: 8 | AD8: 0 | AE8: 0 | AF8: 2 | AG8: 0 | AH8: 2 | AI8: 0 | AJ8: 0 | AK8: 0 | AL8: 0 | AM8: 0 | AN8: 0 | AO8: 0 | AP8: 1 | AQ8: 0 | AR8: 0 | AS8: 1 | AT8: 3 | AU8: 0 | AV8: 0 | AW8: 0 | AX8: 0 | AY8: 24 | AZ8: 0 | BA8: 0 | BB8: 0 | BC8: 0 | BD8: 0 | BE8: 0 | BF8: 15 | BG8: 0 | BH8: 0 | BI8: 0 | BJ8: 0 | BK8: 0 | BL8: 0 | BM8: 0 | BN8: 0 | BO8: 0 | BP8: 0 | BQ8: 0 | BR8: 0 | BS8: 0 | BT8: 6 | BU8: 0 | BV8: 0 | BW8: 0 | BX8: 0 | BY8: 13
A9: E56 | B9: N | C9: 0 | D9: 0 | E9: 0 | F9: 0 | G9: 2 | H9: 0 | I9: 0 | J9: 0 | K9: 0 | L9: 0 | M9: 0 | N9: 0 | O9: 0 | P9: 10 | Q9: 0 | R9: 1 | S9: 0 | T9: 0 | U9: 0 | V9: 0 | W9: 2 | X9: 0 | Y9: 0 | Z9: 14 | AA9: 0 | AB9: 0 | AC9: 0 | AD9: 0 | AE9: 0 | AF9: 0 | AG9: 0 | AH9: 0 | AI9: 0 | AJ9: 0 | AK9: 0 | AL9: 0 | AM9: 0 | AN9: 0 | AO9: 0 | AP9: 0 | AQ9: 0 | AR9: 0 | AS9: 0 | AT9: 1 | AU9: 0 | AV9: 0 | AW9: 0 | AX9: 0 | AY9: 8 | AZ9: 0 | BA9: 0 | BB9: 0 | BC9: 7 | BD9: 0 | BE9: 0 | BF9: 0 | BG9: 0 | BH9: 0 | BI9: 0 | BJ9: 0 | BK9: 1 | BL9: 2 | BM9: 0 | BN9: 0 | BO9: 27 | BP9: 0 | BQ9: 0 | BR9: 0 | BS9: 0 | BT9: 1 | BU9: 0 | BV9: 0 | BW9: 0 | BX9: 0 | BY9: 0
A10: E57 | B10: N | C10: 0 | D10: 0 | E10: 0 | F10: 0 | G10: 3 | H10: 0 | I10: 0 | J10: 3 | K10: 3 | L10: 0 | M10: 0 | N10: 0 | O10: 0 | P10: 0 | Q10: 0 | R10: 2 | S10: 1 | T10: 0 | U10: 0 | V10: 0 | W10: 0 | X10: 0 | Y10: 0 | Z10: 1 | AA10: 0 | AB10: 0 | AC10: 0 | AD10: 1 | AE10: 0 | AF10: 0 | AG10: 0 | AH10: 3 | AI10: 0 | AJ10: 0 | AK10: 0 | AL10: 0 | AM10: 1 | AN10: 0 | AO10: 0 | AP10: 0 | AQ10: 0 | AR10: 0 | AS10: 1 | AT10: 0 | AU10: 0 | AV10: 0 | AW10: 0 | AX10: 0 | AY10: 49 | AZ10: 0 | BA10: 0 | BB10: 2 | BC10: 13 | BD10: 0 | BE10: 0 | BF10: 34 | BG10: 0 | BH10: 0 | BI10: 0 | BJ10: 0 | BK10: 0 | BL10: 0 | BM10: 0 | BN10: 1 | BO10: 7 | BP10: 0 | BQ10: 0 | BR10: 0 | BS10: 0 | BT10: 1 | BU10: 0 | BV10: 1 | BW10: 0 | BX10: 0 | BY10: 7
A11: E60 | B11: N | C11: 0 | D11: 0 | E11: 0 | F11: 0 | G11: 1 | H11: 0 | I11: 0 | J11: 0 | K11: 1 | L11: 0 | M11: 0 | N11: 0 | O11: 0 | P11: 0 | Q11: 0 | R11: 0 | S11: 0 | T11: 0 | U11: 0 | V11: 0 | W11: 0 | X11: 0 | Y11: 0 | Z11: 3 | AA11: 0 | AB11: 0 | AC11: 0 | AD11: 0 | AE11: 0 | AF11: 0 | AG11: 0 | AH11: 0 | AI11: 0 | AJ11: 0 | AK11: 0 | AL11: 0 | AM11: 0 | AN11: 0 | AO11: 0 | AP11: 0 | AQ11: 0 | AR11: 0 | AS11: 0 | AT11: 0 | AU11: 0 | AV11: 0 | AW11: 0 | AX11: 0 | AY11: 64 | AZ11: 0 | BA11: 0 | BB11: 0 | BC11: 0 | BD11: 0 | BE11: 0 | BF11: 31 | BG11: 0 | BH11: 0 | BI11: 0 | BJ11: 0 | BK11: 1 | BL11: 0 | BM11: 0 | BN11: 0 | BO11: 0 | BP11: 0 | BQ11: 0 | BR11: 0 | BS11: 0 | BT11: 6 | BU11: 0 | BV11: 0 | BW11: 0 | BX11: 0 | BY11: 2
A12: E61 | B12: N | C12: 0 | D12: 0 | E12: 1 | F12: 0 | G12: 1 | H12: 0 | I12: 0 | J12: 0 | K12: 1 | L12: 0 | M12: 0 | N12: 0 | O12: 0 | P12: 0 | Q12: 0 | R12: 0 | S12: 0 | T12: 1 | U12: 0 | V12: 0 | W12: 13 | X12: 0 | Y12: 0 | Z12: 26 | AA12: 3 | AB12: 0 | AC12: 0 | AD12: 0 | AE12: 0 | AF12: 0 | AG12: 0 | AH12: 1 | AI12: 0 | AJ12: 0 | AK12: 0 | AL12: 2 | AM12: 0 | AN12: 0 | AO12: 1 | AP12: 0 | AQ12: 0 | AR12: 0 | AS12: 1 | AT12: 0 | AU12: 0 | AV12: 0 | AW12: 0 | AX12: 0 | AY12: 48 | AZ12: 0 | BA12: 0 | BB12: 0 | BC12: 1 | BD12: 0 | BE12: 3 | BF12: 33 | BG12: 1 | BH12: 0 | BI12: 0 | BJ12: 0 | BK12: 19 | BL12: 0 | BM12: 0 | BN12: 0 | BO12: 0 | BP12: 0 | BQ12: 2 | BR12: 0 | BS12: 0 | BT12: 37 | BU12: 0 | BV12: 0 | BW12: 0 | BX12: 0 | BY12: 0
A13: E62 | B13: M | C13: 1 | D13: 0 | E13: 0 | F13: 0 | G13: 0 | H13: 0 | I13: 0 | J13: 0 | K13: 0 | L13: 0 | M13: 0 | N13: 0 | O13: 0 | P13: 0 | Q13: 0 | R13: 0 | S13: 0 | T13: 0 | U13: 0 | V13: 0 | W13: 1 | X13: 0 | Y13: 0 | Z13: 1 | AA13: 0 | AB13: 0 | AC13: 0 | AD13: 0 | AE13: 0 | AF13: 0 | AG13: 0 | AH13: 0 | AI13: 0 | AJ13: 0 | AK13: 0 | AL13: 0 | AM13: 0 | AN13: 0 | AO13: 0 | AP13: 0 | AQ13: 0 | AR13: 0 | AS13: 0 | AT13: 1 | AU13: 0 | AV13: 0 | AW13: 0 | AX13: 0 | AY13: 0 | AZ13: 0 | BA13: 0 | BB13: 0 | BC13: 0 | BD13: 0 | BE13: 0 | BF13: 0 | BG13: 0 | BH13: 0 | BI13: 0 | BJ13: 0 | BK13: 0 | BL13: 0 | BM13: 0 | BN13: 0 | BO13: 0 | BP13: 3 | BQ13: 0 | BR13: 0 | BS13: 0 | BT13: 2 | BU13: 0 | BV13: 0 | BW13: 0 | BX13: 4 | BY13: 0
... A23: E80 | B23: S | C23: 2 | D23: 0 | E23: 1 | F23: 0 | G23: 0 | H23: 1 | I23: 0 | J23: 0 | K23: 0 | L23: 0 | M23: 0 | N23: 0 | O23: 0 | P23: 4 | Q23: 0 | R23: 0 | S23: 0 | T23: 0 | U23: 0 | V23: 0 | W23: 0 | X23: 0 | Y23: 0 | Z23: 2 | AA23: 0 | AB23: 0 | AC23: 0 | AD23: 0 | AE23: 0 | AF23: 0 | AG23: 0 | AH23: 0 | AI23: 0 | AJ23: 0 | AK23: 0 | AL23: 1 | AM23: 0 | AN23: 0 | AO23: 0 | AP23: 0 | AQ23: 0 | AR23: 0 | AS23: 0 | AT23: 0 | AU23: 0 | AV23: 0 | AW23: 0 | AX23: 0 | AY23: 3 | AZ23: 0 | BA23: 0 | BB23: 0 | BC23: 0 | BD23: 0 | BE23: 0 | BF23: 0 | BG23: 0 | BH23: 0 | BI23: 0 | BJ23: 0 | BK23: 0 | BL23: 0 | BM23: 0 | BN23: 0 | BO23: 0 | BP23: 0 | BQ23: 0 | BR23: 0 | BS23: 0 | BT23: 5 | BU23: 0 | BV23: 0 | BW23: 0 | BX23: 0 | BY23: 5

Sheet rasgos
A1: Abrev | B1: LatinName | C1: Family | D1: Guild | E1: TrophicLevel | F1: BodyLengthMax | G1: omnivory | H1: herbivory | I1: invertivory | J1: piscivory | K1: planktivory
A2: Acnpo | B2: Acanthostracion polygonius | C2: Ostraciidae | D2: invertívoro de presas sésiles | E2: 2 | F2: 50 | G2: 0 | H2: 0 | I2: 1 | J2: 0 | K2: 0
A3: Acnba | B3: Acanthurus bahianus | C3: Acanthuridae | D3: herbívoro-detritívoro | E3: 2 | F3: 38.1 | G3: 0 | H3: 1 | I3: 0 | J3: 0 | K3: 0
A4: Achl | B4: Achirus lineatus | C4: Achiridae | D4: invertívoro de presas móviles | E4: 3.52 | F4: 33.1 | G4: 0 | H4: 0 | I4: 1 | J4: 0 | K4: 0
A5: Antpa | B5: Antennarius pauciradiatus | C5: Antennariidae | D5: piscívoro | E5: 3.6 | F5: 6.3 | G5: 0 | H5: 0 | I5: 0 | J5: 1 | K5: 0
A6: Ants | B6: Antennarius striatus | C6: Antennariidae | D6: piscívoro | E6: 4.2 | F6: 25 | G6: 0 | H6: 0 | I6: 0 | J6: 1 | K6: 0
A7: Apgau | B7: Apogon aurolineatus | C7: Apogonidae | D7: planctívoro | E7: 3.4 | F7: 6.5 | G7: 0 | H7: 0 | I7: 0 | J7: 0 | K7: 1
A8: Apgpi | B8: Apogon pillionatus | C8: Apogonidae | D8: invertívoro de presas móviles | E8: 3.4 | F8: 6.5 | G8: 0 | H8: 0 | I8: 1 | J8: 0 | K8: 0
A9: Apgps | B9: Apogon pseudomaculatus | C9: Apogonidae | D9: invertívoro de presas móviles | E9: 3.4 | F9: 11 | G9: 0 | H9: 0 | I9: 1 | J9: 0 | K9: 0
A10: Apgq | B10: Apogon quadrisquamatus | C10: Apogonidae | D10: planctívoro | E10: 3.4 | F10: 7 | G10: 0 | H10: 0 | I10: 0 | J10: 0 | K10: 1
A11: Asta | B11: Astrapogon alutus | C11: Apogonidae | D11: planctívoro | E11: 3.4 | F11: 6.5 | G11: 0 | H11: 0 | I11: 0 | J11: 0 | K11: 1
A12: Alsm | B12: Aulostomus maculatus | C12: Aulostomidae | D12: piscívoro | E12: 4.3 | F12: 100 | G12: 0 | H12: 0 | I12: 0 | J12: 1 | K12: 0
A13: Bllb | B13: Bollmannia boqueronensis | C13: Gobiidae | D13: invertívoro de presas móviles | E13: 3.4 | F13: 10 | G13: 0 | H13: 0 | I13: 1 | J13: 0 | K13: 0
... A76: Upnp | B76: Upeneus parvus | C76: Mullidae | D76: invertívoro de presas móviles | E76: 3.9 | F76: 30 | G76: 0 | H76: 0 | I76: 1 | J76: 0 | K76: 0

Sheet coord
A1: Code | B1: Station | C1: Campaign | D1: Year | E1: Depth_m | F1: Longitude | G1: Latitude
A2: E44 | B2: G201 | C2: Macrofauna II | D2: 2001 | E2: 21 | F2: -71.702457 | G2: 12.476117
A3: E45 | B3: G71 | C3: Macrofauna II | D3: 2001 | E3: 72.5 | F3: -71.729445 | G3: 12.49204
A4: E48 | B4: G72 | C4: Macrofauna II | D4: 2001 | E4: 70 | F4: -72.638201 | G4: 12.055681
A5: E49 | B5: G22 | C5: Macrofauna II | D5: 2001 | E5: 21.5 | F5: -72.61572 | G5: 11.887177
A6: E51 | B6: P71 | C6: Macrofauna II | D6: 2001 | E6: 71 | F6: -73.469445 | G6: 11.403711
A7: E52 | B7: P201 | C7: Macrofauna II | D7: 2001 | E7: 20.5 | F7: -73.459093 | G7: 11.293441
A8: E53 | B8: P72 | C8: Macrofauna II | D8: 2001 | E8: 70.5 | F8: -73.777617 | G8: 11.308185
A9: E56 | B9: T21 | C9: Macrofauna II | D9: 2001 | E9: 27.5 | F9: -74.090717 | G9: 11.337578
A10: E57 | B10: T71 | C10: Macrofauna II | D10: 2001 | E10: 75 | F10: -74.105417 | G10: 11.357372
A11: E60 | B11: T72 | C11: Macrofauna II | D11: 2001 | E11: 72 | F11: -74.177222 | G11: 11.342222
A12: E61 | B12: T22 | C12: Macrofauna II | D12: 2001 | E12: 32.5 | F12: -74.165066 | G12: 11.30477
A13: E62 | B13: M21 | C13: Macrofauna II | D13: 2001 | E13: 20 | F13: -74.676784 | G13: 11.097868
... A23: E80 | B23: M201 | C23: Macrofauna II | D23: 2001 | E23: 20 | F23: -75.711162 | G23: 9.7754021

Sheet amb
A1: Sites | B1: Zone1 | C1: Ecoregion | D1: Depth_class | E1: Longitude | F1: Latitude | G1: Depth_m | H1: Dist_km | I1: T | J1: Sal | K1: Den | L1: O2 | M1: Chla
A2: E44 | B2: N | C2: G | D2: 20m | E2: -71.702457 | F2: 12.476117 | G2: 21 | H2: 18.1 | I2: 25.2747 | J2: 36.80706 | K2: 24.71349 | L2: 6.983818 | M2: 0.5
A3: E45 | B3: N | C3: G | D3: 70m | E3: -71.729445 | F3: 12.49204 | G3: 72.5 | H3: 14.7 | I3: 22.92017 | J3: 36.8465 | K3: 25.66913 | L3: 5.881363 | M3: 0.3090909
A4: E48 | B4: N | C4: G | D4: 70m | E4: -72.638201 | F4: 12.055681 | G4: 70 | H4: 229.5 | I4: 24.442611 | J4: 36.755939 | K4: 25.139944 | L4: 6.1338889 | M4: 0.34545455
A5: E49 | B5: N | C5: G | D5: 20m | E5: -72.61572 | F5: 11.887177 | G5: 21.5 | H5: 248.4 | I5: 25.783833 | J5: 36.744591 | K5: 24.508148 | L5: 6.9725 | M5: 0.2
A6: E51 | B6: N | C6: P | D6: 70m | E6: -73.469445 | F6: 11.403711 | G6: 71 | H6: 387.3 | I6: 24.7206 | J6: 36.704709 | K6: 25.021043 | L6: 6.11 | M6: 0.33
A7: E52 | B7: N | C7: P | D7: 20m | E7: -73.459093 | F7: 11.293441 | G7: 20.5 | H7: 375.1 | I7: 25.911458 | J7: 36.609477 | K7: 24.361868 | L7: 6.79875 | M7: 0.275
A8: E53 | B8: N | C8: P | D8: 70m | E8: -73.777617 | F8: 11.308185 | G8: 70.5 | H8: 460.6 | I8: 24.724958 | J8: 36.705545 | K8: 25.016047 | L8: 6.12 | M8: 0.3125
A9: E56 | B9: N | C9: T | D9: 20m | E9: -74.090717 | F9: 11.337578 | G9: 27.5 | H9: 505.9 | I9: 26.57025 | J9: 36.368659 | K9: 24.002197 | L9: 6.9441667 | M9: 0.37272727
A10: E57 | B10: N | C10: T | D10: 70m | E10: -74.105417 | F10: 11.357372 | G10: 75 | H10: 508.6 | I10: 24.596583 | J10: 36.68575 | K10: 25.061643 | L10: 6.2545833 | M10: 0.27727273
A11: E60 | B11: N | C11: T | D11: 70m | E11: -74.177222 | F11: 11.342222 | G11: 72 | H11: 542.2 | I11: 24.984542 | J11: 36.667068 | K11: 24.916165 | L11: 6.4025 | M11: 0.36136364
A12: E61 | B12: N | C12: T | D12: 20m | E12: -74.165066 | F12: 11.30477 | G12: 32.5 | H12: 545.9 | I12: 26.548042 | J12: 36.383068 | K12: 24.041571 | L12: 6.9425 | M12: 0.4
A13: E62 | B13: M | C13: M | D13: 20m | E13: -74.676784 | F13: 11.097868 | G13: 20 | H13: 652.1 | I13: 26.726458 | J13: 36.35425 | K13: 23.911544 | L13: 6.8816667 | M13: 0.2
... A23: E80 | B23: S | C23: Mor | D23: 20m | E23: -75.711162 | F23: 9.7754021 | G23: 20 | H23: 942.6 | I23: 28.852625 | J23: 36.003318 | K23: 22.95246 | L23: 6.8529167 | M23: 0.1

Sheet rasgos_extra
A1: LatinName | B1: Diet_code | C1: Home_range | D1: Diel_activity | E1: Size_group | F1: Level_water | G1: Body_shape | H1: Caudal_fin | I1: Mouth_position | J1: Spawning | K1: Depth_max | L1: Aspect_ratio | M1: Atlantico | N1: Caribe_Prov12
A2: Acanthostracion polygonius | B2: is | C2: mob | D2: day | E2: sol | F2: low | G2: box_shaped | H2: rounded | I2: subterminal | J2: pelagic | K2: 80 | L2: 0.375069 | M2: 1 | N2: 1
A3: Acanthurus bahianus | B3: hd | C3: mob | D3: day | E3: medg | F3: low | G3: compressed | H3: truncated | I3: terminal | J3: pelagic | K3: 40 | L3: 2.43 | M3: 1 | N3: 0
A4: Achirus lineatus | B4: im | C4: sed | D4: night | E4: sol | F4: bottom | G4: depressed | H4: rounded | I4: terminal | K4: 20 | L4: 1.21399 | M4: 1 | N4: 1
A5: Antennarius pauciradiatus | B5: fc | C5: sed | D5: night | E5: sol | F5: bottom | G5: depressed | H5: rounded | I5: superior | J5: attach | K5: 73 | M5: 1 | N5: 1
A6: Antennarius striatus | B6: fc | C6: sed | D6: night | E6: sol | F6: bottom | G6: depressed | H6: rounded | I6: superior | J6: attach | K6: 219 | L6: 1.055225 | M6: 1 | N6: 1
A7: Apogon aurolineatus | B7: pk | C7: sed | D7: night | E7: sol | F7: low | G7: fusiform | H7: forked | I7: terminal | J7: oral | K7: 75 | M7: 1 | N7: 1
A8: Apogon pillionatus | B8: im | C8: sed | D8: night | E8: sol | F8: low | G8: fusiform | H8: forked | I8: terminal | J8: oral | K8: 90 | M8: 1 | N8: 1
A9: Apogon pseudomaculatus | B9: im | C9: sed | D9: night | E9: sol | F9: low | G9: fusiform | H9: forked | I9: terminal | J9: oral | K9: 100 | L9: 0.704794 | M9: 1 | N9: 1
A10: Apogon quadrisquamatus | B10: pk | C10: sed | D10: night | E10: smallg | F10: low | G10: fusiform | H10: forked | I10: terminal | J10: oral | K10: 75 | L10: 1.20516 | M10: 1 | N10: 1
A11: Astrapogon alutus | B11: pk | C11: sed | D11: night | E11: sol | F11: low | G11: fusiform | H11: truncated | I11: terminal | J11: oral | K11: 48.5 | L11: 1.12621 | M11: 1 | N11: 1
A12: Aulostomus maculatus | B12: fc | C12: mob | D12: day | E12: smallg | F12: low | G12: elongated | H12: rounded | I12: tubular | J12: pelagic | K12: 25 | L12: 1.2398 | M12: 1 | N12: 1
A13: Bollmannia boqueronensis | B13: im | C13: sed | D13: day | E13: sol | F13: bottom | G13: elongated | H13: lanceolated | I13: terminal | J13: demersal | K13: 73 | L13: 0.4623 | M13: 1 | N13: 1
A14: Bothus lunatus | B14: fc | C14: sed | D14: day | E14: sol | F14: bottom | G14: depressed | H14: rounded | I14: terminal | J14: pelagic | K14: 100 | L14: 1.03155 | M14: 1 | N14: 1
A15: Bothus ocellatus | B15: im | C15: mob | D15: both | E15: sol | F15: bottom | G15: depressed | H15: lanceolated | I15: terminal | J15: pelagic | K15: 110 | L15: 1.04347 | M15: 1 | N15: 1
A16: Calamus pennatula | B16: im | C16: mob | D16: day | E16: medg | F16: low | G16: compressed | H16: forked | I16: terminal | J16: pelagic | K16: 85 | L16: 3.79916 | M16: 1 | N16: 1
A17: Callionymus bairdi | B17: im | C17: sed | D17: day | E17: sol | F17: bottom | G17: elongated | H17: truncated | I17: terminal | J17: pelagic | K17: 91 | L17: 0.472614 | M17: 1 | N17: 1
A18: Chaetodon sedentarius | B18: im | C18: sed | D18: day | E18: pair | F18: low | G18: compressed | H18: truncated | I18: terminal | J18: pelagic | K18: 92 | L18: 2.11002 | M18: 1 | N18: 1
A19: Chilomycterus antillarum | B19: im | C19: sed | D19: day | E19: sol | F19: low | G19: box_shaped | H19: rounded | I19: subterminal | J19: pelagic | K19: 44 | L19: 0.955139 | M19: 1 | N19: 1
A20: Chloroscombrus chrysurus | B20: pk | C20: vmob | D20: day | E20: largeg | F20: high | G20: compressed | H20: forked | I20: superior | J20: pelagic | K20: 110 | L20: 3.24179 | M20: 1 | N20: 1
... A22: Dactylopterus volitans | B22: im | C22: sed | D22: both | E22: sol | F22: bottom | G22: fusiform | H22: truncated | I22: subterminal | J22: pelagic | K22: 100 | L22: 1.47427 | M22: 1 | N22: 1
A23: Diapterus rhombeus | B23: om | F23: bottom | G23: fusiform | H23: forked | I23: terminal | J23: pelagic | K23: 70 | L23: 0.817827 | M23: 1 | N23: 1
A24: Diodon holocanthus | B24: im | C24: mob | D24: both | E24: sol | F24: bottom | G24: box_shaped | H24: truncated | I24: terminal | J24: pelagic | K24: 200 | L24: 0.787045 | M24: 1 | N24: 1
A25: Diplectrum bivittatum | B25: im | C25: mob | D25: day | E25: sol | F25: bottom | G25: fusiform | H25: forked | I25: terminal | J25: pelagic | K25: 120 | L25: 1.4157 | M25: 1 | N25: 1
A26: Diplogrammus pauciradiatus | B26: im | C26: sed | D26: day | E26: sol | F26: bottom | G26: elongated | H26: lanceolated | I26: terminal | J26: pelagic | K26: 10 | L26: 0.661672 | M26: 1 | N26: 1
A27: Eucinostomus argenteus | B27: im | C27: mob | D27: night | E27: largeg | F27: low | G27: fusiform | H27: forked | I27: terminal | J27: pelagic | K27: 12 | L27: 2.35299 | M27: 1 | N27: 1
A28: Eucinostomus gula | B28: im | C28: mob | D28: night | E28: largeg | F28: low | G28: fusiform | H28: forked | I28: terminal | J28: pelagic | K28: 55 | L28: 2.13154 | M28: 1 | N28: 1
A29: Fistularia tabacaria | B29: fc | C29: mob | D29: day | E29: sol | F29: low | G29: elongated | H29: forked | I29: tubular | J29: pelagic | K29: 200 | M29: 1 | N29: 1
A30: Gymnothorax ocellatus | B30: im | C30: sed | D30: both | E30: sol | F30: bottom | G30: eel_like | H30: pointed | I30: terminal | J30: pelagic | K30: 170 | M30: 1 | N30: 1
A31: Haemulon aurolineatum | B31: im | C31: mob | D31: both | E31: largeg | F31: low | G31: fusiform | H31: forked | I31: terminal | J31: pelagic | K31: 40 | L31: 2.10255 | M31: 1 | N31: 1
A32: Halichoeres pictus | B32: im | C32: mob | D32: day | E32: sol | F32: low | G32: fusiform | H32: truncated | I32: terminal | J32: pelagic | K32: 25 | L32: 1.39105 | M32: 1 | N32: 1
A33: Halieutichthys aculeatus | B33: im | C33: sed | D33: night | E33: sol | F33: bottom | G33: depressed | H33: rounded | I33: subterminal | K33: 820 | M33: 1 | N33: 1
A34: Hippocampus erectus | B34: im | C34: sed | D34: day | E34: sol | F34: bottom | H34: pointed | I34: tubular | J34: live | K34: 100 | M34: 1 | N34: 1
A35: Holocentrus adscensionis | B35: im | C35: sed | D35: both | E35: sol | F35: low | G35: fusiform | H35: forked | I35: terminal | J35: pelagic | K35: 180 | L35: 2.109165 | M35: 1 | N35: 1
A36: Lutjanus analis | B36: im | C36: mob | D36: day | E36: smallg | F36: low | G36: fusiform | H36: truncated | I36: terminal | J36: pelagic | K36: 95 | L36: 1.6903 | M36: 1 | N36: 1
A37: Lutjanus synagris | B37: im | C37: mob | D37: day | E37: smallg | F37: low | G37: fusiform | H37: truncated | I37: terminal | J37: pelagic | K37: 400 | L37: 1.46359 | M37: 1 | N37: 1
A38: Monacanthus ciliatus | B38: im | C38: mob | D38: day | E38: sol | F38: low | G38: compressed | H38: rounded | I38: terminal | J38: demersal | K38: 50 | L38: 1.45086 | M38: 1 | N38: 1
A39: Myripristis jacobus | B39: im | C39: sed | D39: both | E39: medg | F39: low | G39: fusiform | H39: forked | I39: terminal | J39: pelagic | K39: 210 | L39: 2.76841 | M39: 1 | N39: 1
A40: Ogcocephalus parvus | B40: im | C40: sed | D40: night | E40: sol | F40: bottom | G40: depressed | H40: rounded | I40: subterminal | K40: 126 | M40: 1 | N40: 1
A41: Ogcocephalus pumilus | B41: im | C41: sed | D41: night | E41: sol | F41: bottom | G41: depressed | H41: rounded | I41: subterminal | K41: 348 | M41: 1 | N41: 1
...

Sheet tax_completa
A1: Sites | B1: Sites1 | C1: Acanthostracion polygonius | D1: Acanthurus bahianus | E1: Achirus lineatus | F1: Anchoa cf. lyolepis | G1: Anchoa cubana | H1: Antennarius bermudensis | I1: Antennarius pauciradiatus | J1: Antennarius striatus | K1: Antigonia capros | L1: Apogon affinis | M1: Apogon aurolineatus | N1: Apogon pillionatus | O1: Apogon pseudomaculatus | P1: Apogon quadrisquamatus | Q1: Astrapogon alutus | R1: Aulostomus maculatus | S1: Bathyanthias mexicanus | T1: Bellator brachychir | U1: Bellator riberoi | V1: Bembrops anatirostris | W1: Bollmannia boqueronensis | X1: Bollmannia sp. | Y1: Bothus lunatus | Z1: Bothus ocellatus | AA1: Bregmaceros atlanticus | AB1: Calamus pennatula | AC1: Callionymus bairdi | AD1: Chaetodon sedentarius | AE1: Chilomycterus antillarum | AF1: Chirocentrodon bleekerianus | AG1: Chloroscombrus chrysurus | AH1: Chromis insolata | AI1: Citharichthys cornutus | AJ1: Citharichthys gymnorhinus | AK1: Citharichthys macrops | AL1: Citharichthys spilopterus | AM1: Ctenosciaena gracilicirrhus | AN1: Cyclopsetta chittendeni | AO1: Dactylopterus volitans | AP1: Diapterus rhombeus | AQ1: Dibranchus atlanticus | AR1: Diodon holocanthus | AS1: Diplectrum bivittatum | AT1: Diplobatis colombiensis | AU1: Diplobatis guamachensis | AV1: Diplogrammus pauciradiatus | AW1: Emblemaria sp. | AX1: Engyophrys sentus | AY1: Epinephelus niveatus | AZ1: Equetus sp. | BA1: Etropus crossotus | BB1: Eucinostomus argenteus | BC1: Eucinostomus gula | BD1: Eucinostomus harengulus | BE1: Fistularia tabacaria | BF1: Gobionellus sp. | BG1: Gymnachirus nudus | BH1: Gymnothorax ocellatus | BI1: Haemulon aurolineatum | BJ1: Halichoeres pictus | BK1: Halichoeres sp. | BL1: Halieutichthys aculeatus | BM1: Hemanthias vivanus | BN1: Hippocampus erectus | BO1: Holocentrus adscensionis | BP1: Isopisthus parvipinnis | BQ1: Lagocephalus lagocephalus | BR1: Larimus breviceps | BS1: Lepophidium pheromystax | BT1: Lepophidium sp1. | BU1: Lonchopisthus lemur | BV1: Lutjanus analis | BW1: Lutjanus synagris | BX1: Macrodon ancylodon | BY1: Monacanthus ciliatus | BZ1: Myripristis jacobus | CA1: Neobythites gilli | CB1: Neomerinthe beanorum | CC1: Ogcocephalus parvus | CD1: Ogcocephalus pumilus | CE1: Ogcocephalus sp. | CF1: Ophichthus cruentifer | CG1: Pellona harroweri | CH1: Peprilus paru | CI1: Poecilopsetta inermis | CJ1: Pontinus rathbuni | CK1: Porichthys pauciradiatus | CL1: Porichthys plectrodon | CM1: Priacanthus arenatus | CN1: Prionotus beanii | CO1: Prionotus punctatus | CP1: Prionotus sp. | CQ1: Prionotus stearnsi | CR1: Pristipomoides aquilonaris | CS1: Pristipomoides macrophthalmus | CT1: Pronotogrammus martinicensis | CU1: Pseudupeneus maculatus | CV1: Rhinobatos percellens | CW1: Rhynchoconger flavus | CX1: Rypticus bistrispinus | CY1: Saurida brasiliensis | CZ1: Saurida normani | DA1: Saurida sp. | DB1: Scorpaena albifimbria | DC1: Scorpaena bergii | DD1: Scorpaena calcarata | DE1: Scorpaena isthmensis | DF1: Selar sp. | DG1: Selene brownii | DH1: Serraniculus pumilio | DI1: Serranus atrobranchus | DJ1: Serranus chionaraia | DK1: Serranus flaviventris | DL1: Serranus phoebe | DM1: Serranus sp1. | DN1: Serranus tortugarum | DO1: Sphoeroides dorsalis | DP1: Sphoeroides georgemilleri | DQ1: Sphoeroides sp. | DR1: Sphoeroides spengleri | DS1: Starksia nanodes | DT1: Stellifer microps | DU1: Stellifer sp. | DV1: Stephanolepis setifer | DW1: Syacium gunteri | DX1: Syacium micrurum | DY1: Syacium papillosum | DZ1: Symphurus caribbeanus | EA1: Symphurus diomedeanus | EB1: Symphurus hernandezi | EC1: Symphurus parvus | ED1: Symphurus pelicanus | EE1: Symphurus piger | EF1: Symphurus sp. | EG1: Symphurus tesellatus | EH1: Synagrops bellus | EI1: Synagrops spinosus | EJ1: Synodus foetens | EK1: Synodus intermedius | EL1: Synodus poeyi | EM1: Synodus saurus | EN1: Synodus synodus | EO1: Thalassophryne maculosa | EP1: Trachinocephalus myops | EQ1: Trichiurus lepturus | ER1: Trichopsetta caribbaea | ES1: Upeneus parvus | ET1: Urobatis jamaicensis | EU1: Uroconger syringinus
A2: E44 | B2: N | C2: 0 | D2: 0 | E2: 0 | F2: 0 | G2: 1 | H2: 0 | I2: 0 | J2: 0 | K2: 0 | L2: 0 | M2: 0 | N2: 0 | O2: 0 | P2: 0 | Q2: 0 | R2: 0 | S2: 0 | T2: 0 | U2: 0 | V2: 0 | W2: 0 | X2: 0 | Y2: 0 | Z2: 0 | AA2: 0 | AB2: 0 | AC2: 0 | AD2: 0 | AE2: 0 | AF2: 7 | AG2: 20 | AH2: 0 | AI2: 1 | AJ2: 0 | AK2: 0 | AL2: 0 | AM2: 58 | AN2: 0 | AO2: 0 | AP2: 1 | AQ2: 0 | AR2: 0 | AS2: 0 | AT2: 0 | AU2: 0 | AV2: 0 | AW2: 0 | AX2: 0 | AY2: 0 | AZ2: 0 | BA2: 27 | BB2: 0 | BC2: 0 | BD2: 0 | BE2: 0 | BF2: 0 | BG2: 0 | BH2: 0 | BI2: 0 | BJ2: 0 | BK2: 0 | BL2: 1 | BM2: 0 | BN2: 0 | BO2: 0 | BP2: 50 | BQ2: 3 | BR2: 11 | BS2: 0 | BT2: 10 | BU2: 0 | BV2: 0 | BW2: 0 | BX2: 141 | BY2: 0 | BZ2: 0 | CA2: 0 | CB2: 0 | CC2: 0 | CD2: 0 | CE2: 0 | CF2: 0 | CG2: 145 | CH2: 43 | CI2: 0 | CJ2: 0 | CK2: 0 | CL2: 1 | CM2: 0 | CN2: 10 | CO2: 30 | CP2: 0 | CQ2: 0 | CR2: 0 | CS2: 0 | CT2: 0 | CU2: 0 | CV2: 0 | CW2: 7 | CX2: 0 | CY2: 0 | CZ2: 0 | DA2: 0 | DB2: 0 | DC2: 1 | DD2: 0 | DE2: 0 | DF2: 0 | DG2: 23 | DH2: 0 | DI2: 2 | DJ2: 0 | DK2: 0 | DL2: 0 | DM2: 0 | DN2: 0 | DO2: 0 | DP2: 1 | DQ2: 0 | DR2: 0 | DS2: 0 | DT2: 4 | DU2: 32 | DV2: 0 | DW2: 1 | DX2: 0 | DY2: 0 | DZ2: 22 | EA2: 0 | EB2: 0 | EC2: 0 | ED2: 0 | EE2: 0 | EF2: 0 | EG2: 2 | EH2: 0 | EI2: 0 | EJ2: 0 | EK2: 0 | EL2: 0 | EM2: 0 | EN2: 0 | EO2: 0 | EP2: 0 | EQ2: 14 | ER2: 0 | ES2: 0 | ET2: 0 | EU2: 0
A3: E45 | B3: N | C3: 0 | D3: 0 | E3: 0 | F3: 0 | G3: 0 | H3: 0 | I3: 0 | J3: 0 | K3: 0 | L3: 0 | M3: 0 | N3: 0 | O3: 8 | P3: 0 | Q3: 0 | R3: 0 | S3: 0 | T3: 0 | U3: 0 | V3: 0 | W3: 0 | X3: 0 | Y3: 0 | Z3: 1 | AA3: 0 | AB3: 0 | AC3: 0 | AD3: 0 | AE3: 0 | AF3: 0 | AG3: 0 | AH3: 0 | AI3: 0 | AJ3: 1 | AK3: 0 | AL3: 0 | AM3: 0 | AN3: 1 | AO3: 0 | AP3: 0 | AQ3: 0 | AR3: 0 | AS3: 0 | AT3: 0 | AU3: 1 | AV3: 0 | AW3: 0 | AX3: 1 | AY3: 1 | AZ3: 0 | BA3: 1 | BB3: 0 | BC3: 0 | BD3: 0 | BE3: 0 | BF3: 0 | BG3: 0 | BH3: 0 | BI3: 0 | BJ3: 1 | BK3: 1 | BL3: 0 | BM3: 1 | BN3: 0 | BO3: 0 | BP3: 0 | BQ3: 1 | BR3: 0 | BS3: 0 | BT3: 0 | BU3: 0 | BV3: 1 | BW3: 0 | BX3: 3 | BY3: 0 | BZ3: 0 | CA3: 0 | CB3: 1 | CC3: 0 | CD3: 0 | CE3: 0 | CF3: 0 | CG3: 1 | CH3: 0 | CI3: 0 | CJ3: 1 | CK3: 0 | CL3: 0 | CM3: 0 | CN3: 0 | CO3: 0 | CP3: 0 | CQ3: 0 | CR3: 0 | CS3: 5 | CT3: 15 | CU3: 0 | CV3: 0 | CW3: 0 | CX3: 0 | CY3: 42 | CZ3: 0 | DA3: 0 | DB3: 0 | DC3: 0 | DD3: 0 | DE3: 0 | DF3: 0 | DG3: 0 | DH3: 0 | DI3: 25 | DJ3: 4 | DK3: 0 | DL3: 0 | DM3: 25 | DN3: 0 | DO3: 0 | DP3: 0 | DQ3: 0 | DR3: 0 | DS3: 0 | DT3: 1 | DU3: 0 | DV3: 0 | DW3: 17 | DX3: 4 | DY3: 4 | DZ3: 0 | EA3: 0 | EB3: 0 | EC3: 0 | ED3: 1 | EE3: 0 | EF3: 0 | EG3: 0 | EH3: 0 | EI3: 0 | EJ3: 0 | EK3: 0 | EL3: 0 | EM3: 0 | EN3: 0 | EO3: 4 | EP3: 0 | EQ3: 0 | ER3: 4 | ES3: 2 | ET3: 0 | EU3: 0
A4: E48 | B4: N | C4: 0 | D4: 0 | E4: 0 | F4: 0 | G4: 0 | H4: 1 | I4: 0 | J4: 1 | K4: 0 | L4: 9 | M4: 1 | N4: 0 | O4: 14 | P4: 7 | Q4: 0 | R4: 0 | S4: 0 | T4: 0 | U4: 3 | V4: 0 | W4: 0 | X4: 0 | Y4: 0 | Z4: 2 | AA4: 0 | AB4: 0 | AC4: 0 | AD4: 0 | AE4: 0 | AF4: 0 | AG4: 0 | AH4: 0 | AI4: 2 | AJ4: 2 | AK4: 0 | AL4: 0 | AM4: 0 | AN4: 0 | AO4: 0 | AP4: 0 | AQ4: 0 | AR4: 0 | AS4: 10 | AT4: 0 | AU4: 5 | AV4: 0 | AW4: 0 | AX4: 0 | AY4: 0 | AZ4: 0 | BA4: 0 | BB4: 0 | BC4: 0 | BD4: 0 | BE4: 0 | BF4: 0 | BG4: 0 | BH4: 0 | BI4: 4 | BJ4: 0 | BK4: 0 | BL4: 1 | BM4: 0 | BN4: 1 | BO4: 1 | BP4: 0 | BQ4: 0 | BR4: 0 | BS4: 12 | BT4: 0 | BU4: 0 | BV4: 0 | BW4: 0 | BX4: 0 | BY4: 2 | BZ4: 1 | CA4: 0 | CB4: 0 | CC4: 0 | CD4: 0 | CE4: 0 | CF4: 0 | CG4: 0 | CH4: 0 | CI4: 0 | CJ4: 0 | CK4: 0 | CL4: 2 | CM4: 0 | CN4: 0 | CO4: 0 | CP4: 0 | CQ4: 0 | CR4: 1 | CS4: 0 | CT4: 0 | CU4: 0 | CV4: 0 | CW4: 0 | CX4: 0 | CY4: 0 | CZ4: 0 | DA4: 0 | DB4: 0 | DC4: 2 | DD4: 9 | DE4: 1 | DF4: 0 | DG4: 0 | DH4: 0 | DI4: 0 | DJ4: 1 | DK4: 0 | DL4: 4 | DM4: 0 | DN4: 0 | DO4: 0 | DP4: 0 | DQ4: 0 | DR4: 0 | DS4: 1 | DT4: 0 | DU4: 0 | DV4: 1 | DW4: 2 | DX4: 0 | DY4: 0 | DZ4: 0 | EA4: 0 | EB4: 0 | EC4: 1 | ED4: 0 | EE4: 0 | EF4: 0 | EG4: 0 | EH4: 0 | EI4: 0 | EJ4: 0 | EK4: 1 | EL4: 1 | EM4: 0 | EN4: 0 | EO4: 0 | EP4: 0 | EQ4: 0 | ER4: 0 | ES4: 0 | ET4: 0 | EU4: 1
A5: E49 | B5: N | C5: 0 | D5: 0 | E5: 0 | F5: 0 | G5: 0 | H5: 0 | I5: 0 | J5: 0 | K5: 0 | L5: 0 | M5: 0 | N5: 0 | O5: 0 | P5: 0 | Q5: 0 | R5: 0 | S5: 0 | T5: 0 | U5: 0 | V5: 0 | W5: 1 | X5: 0 | Y5: 0 | Z5: 7 | AA5: 0 | AB5: 0 | AC5: 0 | AD5: 0 | AE5: 0 | AF5: 0 | AG5: 0 | AH5: 0 | AI5: 0 | AJ5: 0 | AK5: 0 | AL5: 0 | AM5: 0 | AN5: 0 | AO5: 0 | AP5: 0 | AQ5: 0 | AR5: 0 | AS5: 1 | AT5: 0 | AU5: 0 | AV5: 0 | AW5: 2 | AX5: 0 | AY5: 0 | AZ5: 0 | BA5: 0 | BB5: 0 | BC5: 0 | BD5: 0 | BE5: 0 | BF5: 0 | BG5: 0 | BH5: 0 | BI5: 0 | BJ5: 0 | BK5: 0 | BL5: 0 | BM5: 0 | BN5: 0 | BO5: 0 | BP5: 0 | BQ5: 0 | BR5: 0 | BS5: 0 | BT5: 0 | BU5: 0 | BV5: 0 | BW5: 0 | BX5: 0 | BY5: 0 | BZ5: 0 | CA5: 0 | CB5: 0 | CC5: 0 | CD5: 1 | CE5: 1 | CF5: 0 | CG5: 0 | CH5: 0 | CI5: 0 | CJ5: 0 | CK5: 0 | CL5: 0 | CM5: 0 | CN5: 0 | CO5: 4 | CP5: 0 | CQ5: 0 | CR5: 0 | CS5: 0 | CT5: 0 | CU5: 0 | CV5: 0 | CW5: 0 | CX5: 0 | CY5: 0 | CZ5: 0 | DA5: 0 | DB5: 0 | DC5: 0 | DD5: 0 | DE5: 0 | DF5: 0 | DG5: 0 | DH5: 0 | DI5: 0 | DJ5: 0 | DK5: 0 | DL5: 0 | DM5: 0 | DN5: 0 | DO5: 0 | DP5: 0 | DQ5: 0 | DR5: 1 | DS5: 0 | DT5: 0 | DU5: 0 | DV5: 0 | DW5: 0 | DX5: 0 | DY5: 2 | DZ5: 0 | EA5: 0 | EB5: 0 | EC5: 0 | ED5: 0 | EE5: 0 | EF5: 0 | EG5: 0 | EH5: 0 | EI5: 0 | EJ5: 0 | EK5: 0 | EL5: 0 | EM5: 2 | EN5: 0 | EO5: 0 | EP5: 2 | EQ5: 0 | ER5: 0 | ES5: 0 | ET5: 0 | EU5: 0
A6: E51 | B6: N | C6: 0 | D6: 0 | E6: 0 | F6: 0 | G6: 0 | H6: 0 | I6: 2 | J6: 0 | K6: 1 | L6: 245 | M6: 0 | N6: 0 | O6: 1 | P6: 2 | Q6: 0 | R6: 0 | S6: 1 | T6: 0 | U6: 0 | V6: 1 | W6: 0 | X6: 0 | Y6: 0 | Z6: 0 | AA6: 1 | AB6: 0 | AC6: 1 | AD6: 0 | AE6: 0 | AF6: 0 | AG6: 0 | AH6: 0 | AI6: 0 | AJ6: 2 | AK6: 0 | AL6: 0 | AM6: 0 | AN6: 0 | AO6: 0 | AP6: 0 | AQ6: 3 | AR6: 0 | AS6: 0 | AT6: 0 | AU6: 0 | AV6: 0 | AW6: 0 | AX6: 1 | AY6: 0 | AZ6: 0 | BA6: 0 | BB6: 0 | BC6: 0 | BD6: 0 | BE6: 0 | BF6: 0 | BG6: 0 | BH6: 0 | BI6: 0 | BJ6: 0 | BK6: 0 | BL6: 1 | BM6: 0 | BN6: 0 | BO6: 0 | BP6: 0 | BQ6: 0 | BR6: 0 | BS6: 0 | BT6: 0 | BU6: 0 | BV6: 0 | BW6: 0 | BX6: 0 | BY6: 1 | BZ6: 0 | CA6: 2 | CB6: 0 | CC6: 0 | CD6: 0 | CE6: 0 | CF6: 0 | CG6: 0 | CH6: 0 | CI6: 0 | CJ6: 0 | CK6: 0 | CL6: 0 | CM6: 1 | CN6: 0 | CO6: 0 | CP6: 0 | CQ6: 2 | CR6: 0 | CS6: 0 | CT6: 1 | CU6: 0 | CV6: 0 | CW6: 0 | CX6: 0 | CY6: 23 | CZ6: 0 | DA6: 0 | DB6: 0 | DC6: 0 | DD6: 3 | DE6: 0 | DF6: 0 | DG6: 0 | DH6: 0 | DI6: 5 | DJ6: 24 | DK6: 0 | DL6: 0 | DM6: 3 | DN6: 1 | DO6: 0 | DP6: 0 | DQ6: 0 | DR6: 0 | DS6: 0 | DT6: 0 | DU6: 0 | DV6: 0 | DW6: 2 | DX6: 2 | DY6: 0 | DZ6: 0 | EA6: 0 | EB6: 0 | EC6: 0 | ED6: 0 | EE6: 0 | EF6: 0 | EG6: 0 | EH6: 1 | EI6: 3 | EJ6: 0 | EK6: 0 | EL6: 7 | EM6: 0 | EN6: 0 | EO6: 0 | EP6: 0 | EQ6: 0 | ER6: 0 | ES6: 0 | ET6: 0 | EU6: 0
A7: E52 | B7: N | C7: 0 | D7: 0 | E7: 0 | F7: 0 | G7: 0 | H7: 0 | I7: 0 | J7: 2 | K7: 0 | L7: 0 | M7: 0 | N7: 0 | O7: 0 | P7: 0 | Q7: 0 | R7: 0 | S7: 0 | T7: 0 | U7: 0 | V7: 0 | W7: 0 | X7: 0 | Y7: 0 | Z7: 0 | AA7: 0 | AB7: 0 | AC7: 0 | AD7: 0 | AE7: 0 | AF7: 0 | AG7: 7 | AH7: 0 | AI7: 0 | AJ7: 0 | AK7: 0 | AL7: 0 | AM7: 0 | AN7: 1 | AO7: 0 | AP7: 0 | AQ7: 1 | AR7: 0 | AS7: 4 | AT7: 0 | AU7: 0 | AV7: 0 | AW7: 0 | AX7: 0 | AY7: 0 | AZ7: 0 | BA7: 0 | BB7: 0 | BC7: 4 | BD7: 0 | BE7: 0 | BF7: 0 | BG7: 0 | BH7: 0 | BI7: 0 | BJ7: 0 | BK7: 0 | BL7: 0 | BM7: 0 | BN7: 0 | BO7: 0 | BP7: 0 | BQ7: 0 | BR7: 0 | BS7: 0 | BT7: 0 | BU7: 0 | BV7: 0 | BW7: 3 | BX7: 0 | BY7: 0 | BZ7: 0 | CA7: 0 | CB7: 0 | CC7: 0 | CD7: 0 | CE7: 0 | CF7: 0 | CG7: 0 | CH7: 0 | CI7: 0 | CJ7: 0 | CK7: 0 | CL7: 0 | CM7: 0 | CN7: 0 | CO7: 11 | CP7: 0 | CQ7: 0 | CR7: 0 | CS7: 0 | CT7: 0 | CU7: 0 | CV7: 0 | CW7: 0 | CX7: 0 | CY7: 0 | CZ7: 0 | DA7: 0 | DB7: 0 | DC7: 0 | DD7: 0 | DE7: 0 | DF7: 0 | DG7: 0 | DH7: 0 | DI7: 5 | DJ7: 0 | DK7: 0 | DL7: 0 | DM7: 1 | DN7: 0 | DO7: 0 | DP7: 0 | DQ7: 0 | DR7: 0 | DS7: 0 | DT7: 0 | DU7: 0 | DV7: 2 | DW7: 3 | DX7: 0 | DY7: 0 | DZ7: 0 | EA7: 0 | EB7: 0 | EC7: 0 | ED7: 0 | EE7: 0 | EF7: 0 | EG7: 1 | EH7: 0 | EI7: 0 | EJ7: 3 | EK7: 0 | EL7: 2 | EM7: 0 | EN7: 0 | EO7: 0 | EP7: 0 | EQ7: 0 | ER7: 0 | ES7: 7 | ET7: 0 | EU7: 0
A8: E53 | B8: N | C8: 0 | D8: 0 | E8: 0 | F8: 0 | G8: 0 | H8: 0 | I8: 0 | J8: 1 | K8: 0 | L8: 1 | M8: 0 | N8: 0 | O8: 3 | P8: 13 | Q8: 0 | R8: 0 | S8: 0 | T8: 0 | U8: 0 | V8: 0 | W8: 0 | X8: 0 | Y8: 0 | Z8: 0 | AA8: 0 | AB8: 1 | AC8: 0 | AD8: 0 | AE8: 0 | AF8: 0 | AG8: 0 | AH8: 0 | AI8: 0 | AJ8: 0 | AK8: 0 | AL8: 0 | AM8: 0 | AN8: 0 | AO8: 0 | AP8: 0 | AQ8: 0 | AR8: 0 | AS8: 3 | AT8: 0 | AU8: 0 | AV8: 0 | AW8: 0 | AX8: 4 | AY8: 0 | AZ8: 0 | BA8: 0 | BB8: 0 | BC8: 8 | BD8: 0 | BE8: 0 | BF8: 0 | BG8: 0 | BH8: 0 | BI8: 2 | BJ8: 0 | BK8: 0 | BL8: 2 | BM8: 0 | BN8: 0 | BO8: 0 | BP8: 0 | BQ8: 0 | BR8: 0 | BS8: 0 | BT8: 0 | BU8: 0 | BV8: 0 | BW8: 0 | BX8: 0 | BY8: 0 | BZ8: 0 | CA8: 0 | CB8: 0 | CC8: 0 | CD8: 1 | CE8: 0 | CF8: 0 | CG8: 0 | CH8: 0 | CI8: 0 | CJ8: 0 | CK8: 0 | CL8: 0 | CM8: 1 | CN8: 3 | CO8: 3 | CP8: 0 | CQ8: 1 | CR8: 0 | CS8: 0 | CT8: 0 | CU8: 0 | CV8: 0 | CW8: 0 | CX8: 0 | CY8: 24 | CZ8: 0 | DA8: 0 | DB8: 0 | DC8: 0 | DD8: 0 | DE8: 0 | DF8: 1 | DG8: 0 | DH8: 0 | DI8: 15 | DJ8: 0 | DK8: 0 | DL8: 0 | DM8: 2 | DN8: 0 | DO8: 0 | DP8: 0 | DQ8: 0 | DR8: 0 | DS8: 0 | DT8: 0 | DU8: 0 | DV8: 0 | DW8: 9 | DX8: 0 | DY8: 0 | DZ8: 0 | EA8: 0 | EB8: 0 | EC8: 0 | ED8: 0 | EE8: 0 | EF8: 0 | EG8: 0 | EH8: 0 | EI8: 0 | EJ8: 0 | EK8: 0 | EL8: 6 | EM8: 0 | EN8: 0 | EO8: 0 | EP8: 0 | EQ8: 0 | ER8: 0 | ES8: 13 | ET8: 0 | EU8: 0
A9: E56 | B9: N | C9: 0 | D9: 0 | E9: 0 | F9: 0 | G9: 0 | H9: 0 | I9: 0 | J9: 2 | K9: 0 | L9: 0 | M9: 0 | N9: 0 | O9: 0 | P9: 0 | Q9: 0 | R9: 0 | S9: 0 | T9: 0 | U9: 0 | V9: 0 | W9: 0 | X9: 0 | Y9: 0 | Z9: 10 | AA9: 0 | AB9: 0 | AC9: 1 | AD9: 0 | AE9: 0 | AF9: 0 | AG9: 0 | AH9: 0 | AI9: 0 | AJ9: 0 | AK9: 0 | AL9: 0 | AM9: 0 | AN9: 0 | AO9: 2 | AP9: 0 | AQ9: 1 | AR9: 0 | AS9: 14 | AT9: 0 | AU9: 1 | AV9: 0 | AW9: 0 | AX9: 0 | AY9: 0 | AZ9: 1 | BA9: 0 | BB9: 0 | BC9: 0 | BD9: 0 | BE9: 0 | BF9: 0 | BG9: 0 | BH9: 0 | BI9: 0 | BJ9: 0 | BK9: 0 | BL9: 0 | BM9: 0 | BN9: 0 | BO9: 0 | BP9: 0 | BQ9: 0 | BR9: 0 | BS9: 0 | BT9: 0 | BU9: 0 | BV9: 0 | BW9: 0 | BX9: 0 | BY9: 0 | BZ9: 0 | CA9: 0 | CB9: 0 | CC9: 0 | CD9: 0 | CE9: 0 | CF9: 0 | CG9: 0 | CH9: 0 | CI9: 0 | CJ9: 0 | CK9: 0 | CL9: 0 | CM9: 0 | CN9: 0 | CO9: 1 | CP9: 0 | CQ9: 0 | CR9: 0 | CS9: 0 | CT9: 0 | CU9: 0 | CV9: 0 | CW9: 0 | CX9: 0 | CY9: 8 | CZ9: 0 | DA9: 17 | DB9: 0 | DC9: 0 | DD9: 7 | DE9: 0 | DF9: 0 | DG9: 0 | DH9: 0 | DI9: 0 | DJ9: 0 | DK9: 0 | DL9: 0 | DM9: 1 | DN9: 0 | DO9: 1 | DP9: 0 | DQ9: 0 | DR9: 2 | DS9: 0 | DT9: 0 | DU9: 0 | DV9: 0 | DW9: 7 | DX9: 27 | DY9: 0 | DZ9: 0 | EA9: 0 | EB9: 0 | EC9: 0 | ED9: 0 | EE9: 0 | EF9: 0 | EG9: 0 | EH9: 0 | EI9: 0 | EJ9: 0 | EK9: 0 | EL9: 1 | EM9: 0 | EN9: 0 | EO9: 0 | EP9: 0 | EQ9: 0 | ER9: 0 | ES9: 0 | ET9: 0 | EU9: 0
A10: E57 | B10: N | C10: 0 | D10: 0 | E10: 0 | F10: 0 | G10: 0 | H10: 0 | I10: 0 | J10: 3 | K10: 0 | L10: 0 | M10: 0 | N10: 0 | O10: 3 | P10: 3 | Q10: 0 | R10: 0 | S10: 0 | T10: 0 | U10: 0 | V10: 0 | W10: 0 | X10: 0 | Y10: 0 | Z10: 0 | AA10: 0 | AB10: 0 | AC10: 2 | AD10: 1 | AE10: 0 | AF10: 0 | AG10: 0 | AH10: 0 | AI10: 0 | AJ10: 3 | AK10: 0 | AL10: 0 | AM10: 0 | AN10: 0 | AO10: 0 | AP10: 0 | AQ10: 0 | AR10: 0 | AS10: 1 | AT10: 0 | AU10: 0 | AV10: 0 | AW10: 0 | AX10: 4 | AY10: 0 | AZ10: 0 | BA10: 0 | BB10: 0 | BC10: 0 | BD10: 0 | BE10: 1 | BF10: 0 | BG10: 0 | BH10: 0 | BI10: 0 | BJ10: 0 | BK10: 0 | BL10: 3 | BM10: 0 | BN10: 0 | BO10: 0 | BP10: 0 | BQ10: 0 | BR10: 0 | BS10: 0 | BT10: 0 | BU10: 0 | BV10: 0 | BW10: 0 | BX10: 0 | BY10: 1 | BZ10: 0 | CA10: 0 | CB10: 0 | CC10: 0 | CD10: 0 | CE10: 0 | CF10: 0 | CG10: 0 | CH10: 0 | CI10: 0 | CJ10: 0 | CK10: 0 | CL10: 0 | CM10: 1 | CN10: 1 | CO10: 0 | CP10: 0 | CQ10: 1 | CR10: 0 | CS10: 0 | CT10: 0 | CU10: 0 | CV10: 0 | CW10: 0 | CX10: 0 | CY10: 49 | CZ10: 0 | DA10: 0 | DB10: 0 | DC10: 2 | DD10: 13 | DE10: 0 | DF10: 0 | DG10: 0 | DH10: 0 | DI10: 34 | DJ10: 0 | DK10: 0 | DL10: 0 | DM10: 28 | DN10: 0 | DO10: 0 | DP10: 0 | DQ10: 0 | DR10: 0 | DS10: 0 | DT10: 0 | DU10: 0 | DV10: 1 | DW10: 23 | DX10: 7 | DY10: 0 | DZ10: 0 | EA10: 0 | EB10: 0 | EC10: 0 | ED10: 0 | EE10: 0 | EF10: 0 | EG10: 0 | EH10: 0 | EI10: 0 | EJ10: 0 | EK10: 0 | EL10: 1 | EM10: 0 | EN10: 1 | EO10: 0 | EP10: 0 | EQ10: 0 | ER10: 0 | ES10: 7 | ET10: 0 | EU10: 0
A11: E60 | B11: N | C11: 0 | D11: 0 | E11: 0 | F11: 0 | G11: 0 | H11: 0 | I11: 0 | J11: 1 | K11: 0 | L11: 0 | M11: 0 | N11: 0 | O11: 0 | P11: 1 | Q11: 0 | R11: 0 | S11: 0 | T11: 0 | U11: 0 | V11: 0 | W11: 0 | X11: 0 | Y11: 0 | Z11: 0 | AA11: 0 | AB11: 0 | AC11: 0 | AD11: 0 | AE11: 0 | AF11: 0 | AG11: 0 | AH11: 0 | AI11: 0 | AJ11: 0 | AK11: 0 | AL11: 0 | AM11: 0 | AN11: 0 | AO11: 0 | AP11: 0 | AQ11: 0 | AR11: 0 | AS11: 3 | AT11: 0 | AU11: 0 | AV11: 0 | AW11: 0 | AX11: 2 | AY11: 0 | AZ11: 0 | BA11: 0 | BB11: 0 | BC11: 0 | BD11: 0 | BE11: 0 | BF11: 0 | BG11: 0 | BH11: 0 | BI11: 0 | BJ11: 0 | BK11: 0 | BL11: 0 | BM11: 0 | BN11: 0 | BO11: 0 | BP11: 0 | BQ11: 0 | BR11: 0 | BS11: 0 | BT11: 0 | BU11: 0 | BV11: 0 | BW11: 0 | BX11: 0 | BY11: 0 | BZ11: 0 | CA11: 0 | CB11: 0 | CC11: 0 | CD11: 0 | CE11: 0 | CF11: 0 | CG11: 0 | CH11: 0 | CI11: 0 | CJ11: 0 | CK11: 0 | CL11: 0 | CM11: 0 | CN11: 0 | CO11: 0 | CP11: 0 | CQ11: 9 | CR11: 0 | CS11: 0 | CT11: 0 | CU11: 0 | CV11: 0 | CW11: 0 | CX11: 0 | CY11: 64 | CZ11: 0 | DA11: 0 | DB11: 0 | DC11: 0 | DD11: 0 | DE11: 0 | DF11: 0 | DG11: 0 | DH11: 0 | DI11: 31 | DJ11: 0 | DK11: 0 | DL11: 0 | DM11: 47 | DN11: 0 | DO11: 1 | DP11: 0 | DQ11: 0 | DR11: 0 | DS11: 0 | DT11: 0 | DU11: 0 | DV11: 0 | DW11: 3 | DX11: 0 | DY11: 0 | DZ11: 0 | EA11: 0 | EB11: 0 | EC11: 0 | ED11: 0 | EE11: 0 | EF11: 0 | EG11: 0 | EH11: 0 | EI11: 0 | EJ11: 0 | EK11: 0 | EL11: 6 | EM11: 0 | EN11: 0 | EO11: 0 | EP11: 0 | EQ11: 0 | ER11: 1 | ES11: 2 | ET11: 0 | EU11: 0
A12: E61 | B12: N | C12: 0 | D12: 0 | E12: 1 | F12: 0 | G12: 0 | H12: 0 | I12: 0 | J12: 1 | K12: 0 | L12: 0 | M12: 0 | N12: 0 | O12: 0 | P12: 1 | Q12: 0 | R12: 0 | S12: 0 | T12: 0 | U12: 0 | V12: 0 | W12: 0 | X12: 0 | Y12: 0 | Z12: 0 | AA12: 0 | AB12: 0 | AC12: 0 | AD12: 0 | AE12: 1 | AF12: 0 | AG12: 0 | AH12: 0 | AI12: 0 | AJ12: 0 | AK12: 0 | AL12: 0 | AM12: 0 | AN12: 0 | AO12: 13 | AP12: 0 | AQ12: 1 | AR12: 0 | AS12: 26 | AT12: 0 | AU12: 0 | AV12: 3 | AW12: 0 | AX12: 2 | AY12: 0 | AZ12: 0 | BA12: 0 | BB12: 0 | BC12: 0 | BD12: 0 | BE12: 0 | BF12: 1 | BG12: 0 | BH12: 0 | BI12: 0 | BJ12: 0 | BK12: 0 | BL12: 1 | BM12: 0 | BN12: 0 | BO12: 0 | BP12: 0 | BQ12: 0 | BR12: 0 | BS12: 0 | BT12: 0 | BU12: 0 | BV12: 0 | BW12: 2 | BX12: 0 | BY12: 0 | BZ12: 0 | CA12: 0 | CB12: 0 | CC12: 1 | CD12: 0 | CE12: 1 | CF12: 0 | CG12: 0 | CH12: 0 | CI12: 0 | CJ12: 0 | CK12: 0 | CL12: 0 | CM12: 1 | CN12: 0 | CO12: 0 | CP12: 0 | CQ12: 0 | CR12: 0 | CS12: 0 | CT12: 0 | CU12: 0 | CV12: 1 | CW12: 0 | CX12: 0 | CY12: 48 | CZ12: 0 | DA12: 0 | DB12: 0 | DC12: 0 | DD12: 1 | DE12: 0 | DF12: 0 | DG12: 0 | DH12: 3 | DI12: 33 | DJ12: 1 | DK12: 0 | DL12: 0 | DM12: 10 | DN12: 0 | DO12: 19 | DP12: 0 | DQ12: 0 | DR12: 0 | DS12: 0 | DT12: 0 | DU12: 0 | DV12: 0 | DW12: 36 | DX12: 0 | DY12: 0 | DZ12: 0 | EA12: 2 | EB12: 0 | EC12: 0 | ED12: 0 | EE12: 0 | EF12: 0 | EG12: 0 | EH12: 0 | EI12: 0 | EJ12: 0 | EK12: 0 | EL12: 37 | EM12: 0 | EN12: 0 | EO12: 0 | EP12: 0 | EQ12: 0 | ER12: 0 | ES12: 0 | ET12: 0 | EU12: 0
A13: E62 | B13: M | C13: 1 | D13: 0 | E13: 0 | F13: 0 | G13: 0 | H13: 0 | I13: 0 | J13: 0 | K13: 0 | L13: 0 | M13: 0 | N13: 0 | O13: 0 | P13: 0 | Q13: 0 | R13: 0 | S13: 0 | T13: 0 | U13: 0 | V13: 0 | W13: 0 | X13: 0 | Y13: 0 | Z13: 0 | AA13: 0 | AB13: 0 | AC13: 0 | AD13: 0 | AE13: 0 | AF13: 0 | AG13: 0 | AH13: 0 | AI13: 0 | AJ13: 0 | AK13: 1 | AL13: 0 | AM13: 0 | AN13: 0 | AO13: 1 | AP13: 0 | AQ13: 0 | AR13: 0 | AS13: 1 | AT13: 0 | AU13: 0 | AV13: 0 | AW13: 0 | AX13: 0 | AY13: 0 | AZ13: 0 | BA13: 0 | BB13: 0 | BC13: 0 | BD13: 0 | BE13: 0 | BF13: 0 | BG13: 0 | BH13: 0 | BI13: 0 | BJ13: 0 | BK13: 0 | BL13: 0 | BM13: 0 | BN13: 0 | BO13: 0 | BP13: 0 | BQ13: 0 | BR13: 0 | BS13: 0 | BT13: 0 | BU13: 0 | BV13: 0 | BW13: 0 | BX13: 0 | BY13: 0 | BZ13: 0 | CA13: 0 | CB13: 0 | CC13: 0 | CD13: 0 | CE13: 0 | CF13: 0 | CG13: 0 | CH13: 0 | CI13: 0 | CJ13: 0 | CK13: 0 | CL13: 0 | CM13: 0 | CN13: 0 | CO13: 1 | CP13: 0 | CQ13: 0 | CR13: 0 | CS13: 0 | CT13: 0 | CU13: 0 | CV13: 0 | CW13: 0 | CX13: 0 | CY13: 0 | CZ13: 0 | DA13: 0 | DB13: 0 | DC13: 0 | DD13: 0 | DE13: 0 | DF13: 0 | DG13: 0 | DH13: 0 | DI13: 0 | DJ13: 0 | DK13: 0 | DL13: 0 | DM13: 0 | DN13: 0 | DO13: 0 | DP13: 0 | DQ13: 0 | DR13: 0 | DS13: 0 | DT13: 0 | DU13: 0 | DV13: 0 | DW13: 3 | DX13: 0 | DY13: 3 | DZ13: 0 | EA13: 0 | EB13: 0 | EC13: 0 | ED13: 0 | EE13: 0 | EF13: 0 | EG13: 0 | EH13: 0 | EI13: 0 | EJ13: 0 | EK13: 0 | EL13: 2 | EM13: 0 | EN13: 0 | EO13: 0 | EP13: 4 | EQ13: 0 | ER13: 0 | ES13: 0 | ET13: 0 | EU13: 0
... A23: E80 | B23: S | C23: 2 | D23: 0 | E23: 1 | F23: 1 | G23: 0 | H23: 0 | I23: 0 | J23: 0 | K23: 0 | L23: 0 | M23: 1 | N23: 0 | O23: 0 | P23: 0 | Q23: 0 | R23: 0 | S23: 0 | T23: 0 | U23: 0 | V23: 0 | W23: 0 | X23: 0 | Y23: 0 | Z23: 4 | AA23: 1 | AB23: 0 | AC23: 0 | AD23: 0 | AE23: 0 | AF23: 0 | AG23: 0 | AH23: 0 | AI23: 0 | AJ23: 0 | AK23: 0 | AL23: 0 | AM23: 0 | AN23: 0 | AO23: 0 | AP23: 0 | AQ23: 0 | AR23: 0 | AS23: 2 | AT23: 0 | AU23: 0 | AV23: 0 | AW23: 0 | AX23: 0 | AY23: 0 | AZ23: 0 | BA23: 0 | BB23: 0 | BC23: 0 | BD23: 0 | BE23: 0 | BF23: 0 | BG23: 0 | BH23: 0 | BI23: 0 | BJ23: 0 | BK23: 0 | BL23: 0 | BM23: 0 | BN23: 0 | BO23: 0 | BP23: 0 | BQ23: 0 | BR23: 0 | BS23: 0 | BT23: 0 | BU23: 0 | BV23: 0 | BW23: 1 | BX23: 0 | BY23: 0 | BZ23: 0 | CA23: 0 | CB23: 0 | CC23: 0 | CD23: 0 | CE23: 0 | CF23: 0 | CG23: 0 | CH23: 0 | CI23: 0 | CJ23: 0 | CK23: 0 | CL23: 1 | CM23: 0 | CN23: 0 | CO23: 0 | CP23: 0 | CQ23: 0 | CR23: 0 | CS23: 0 | CT23: 0 | CU23: 0 | CV23: 0 | CW23: 0 | CX23: 0 | CY23: 3 | CZ23: 0 | DA23: 0 | DB23: 0 | DC23: 0 | DD23: 0 | DE23: 0 | DF23: 0 | DG23: 0 | DH23: 0 | DI23: 0 | DJ23: 0 | DK23: 0 | DL23: 0 | DM23: 0 | DN23: 0 | DO23: 0 | DP23: 0 | DQ23: 0 | DR23: 0 | DS23: 0 | DT23: 0 | DU23: 0 | DV23: 0 | DW23: 3 | DX23: 0 | DY23: 0 | DZ23: 0 | EA23: 0 | EB23: 0 | EC23: 0 | ED23: 1 | EE23: 0 | EF23: 0 | EG23: 0 | EH23: 0 | EI23: 0 | EJ23: 0 | EK23: 0 | EL23: 5 | EM23: 0 | EN23: 0 | EO23: 0 | EP23: 0 | EQ23: 0 | ER23: 0 | ES23: 5 | ET23: 0 | EU23: 0

Sheet nombres
A1: NombreOriginal_Vides | B1: NombreLimpio | C1: Tipo | D1: Estado_rasgos | E1: Individuos | F1: Estaciones | G1: Cambio_de_nombre
A2: Acanthostracion poligonius | B2: Acanthostracion polygonius | C2: especie | D2: con rasgos (variante ortográfica corregida) | E2: 6 | F2: 4 | G2: =IF(EXACT(A2,B2),"no","sí") -> sí
A3: Acanthurus bahianus | B3: Acanthurus bahianus | C3: especie | D3: con rasgos (nombre exacto) | E3: 1 | F3: 1 | G3: =IF(EXACT(A3,B3),"no","sí") -> no
A4: Achirus lineatus | B4: Achirus lineatus | C4: especie | D4: con rasgos (nombre exacto) | E4: 7 | F4: 5 | G4: =IF(EXACT(A4,B4),"no","sí") -> no
A5: Anchoa cf. lyolepis | B5: Anchoa cf. lyolepis | C5: morfoespecie | D5: sin rasgos (morfoespecie) | E5: 1 | F5: 1 | G5: =IF(EXACT(A5,B5),"no","sí") -> no
A6: Anchoa cubana | B6: Anchoa cubana | C6: especie | D6: sin rasgos (nombre no encontrado en Quimbayo) | E6: 1 | F6: 1 | G6: =IF(EXACT(A6,B6),"no","sí") -> no
A7: Antennarius bermudensis | B7: Antennarius bermudensis | C7: especie | D7: sin rasgos (nombre no encontrado en Quimbayo) | E7: 1 | F7: 1 | G7: =IF(EXACT(A7,B7),"no","sí") -> no
A8: Antennarius pauciradiatus | B8: Antennarius pauciradiatus | C8: especie | D8: con rasgos (nombre exacto) | E8: 2 | F8: 1 | G8: =IF(EXACT(A8,B8),"no","sí") -> no
A9: Antennarius striatus | B9: Antennarius striatus | C9: especie | D9: con rasgos (nombre exacto) | E9: 11 | F9: 7 | G9: =IF(EXACT(A9,B9),"no","sí") -> no
A10: Antigonia capros | B10: Antigonia capros | C10: especie | D10: sin rasgos (nombre no encontrado en Quimbayo) | E10: 1 | F10: 1 | G10: =IF(EXACT(A10,B10),"no","sí") -> no
A11: Apogon affinis | B11: Apogon affinis | C11: especie | D11: sin rasgos (nombre no encontrado en Quimbayo) | E11: 261 | F11: 5 | G11: =IF(EXACT(A11,B11),"no","sí") -> no
A12: Apogon aurolineatus | B12: Apogon aurolineatus | C12: especie | D12: con rasgos (nombre exacto) | E12: 41 | F12: 5 | G12: =IF(EXACT(A12,B12),"no","sí") -> no
A13: Apogon pillionatus | B13: Apogon pillionatus | C13: especie | D13: con rasgos (nombre exacto) | E13: 1 | F13: 1 | G13: =IF(EXACT(A13,B13),"no","sí") -> no
... A150: Uroconger syringinus | B150: Uroconger syringinus | C150: especie | D150: sin rasgos (nombre no encontrado en Quimbayo) | E150: 1 | F150: 1 | G150: =IF(EXACT(A150,B150),"no","sí") -> no

Sheet notas
A1: Peces de la plataforma somera (≤ 100 m) del Caribe colombiano: subconjunto de Vides (2011) con rasgos de Quimbayo et al. (2021), en el formato del taller
A3: 1. Fuentes y créditos
A4: Abundancias y variables ambientales: Vides, M.P. (2011). Distribución de la megafauna bentónica del Caribe colombiano asociada a variables ambientales del fondo marino. Boletín de Investigaciones Marinas y Costeras, 40(2), 249–270. Datos de INVEMAR (expediciones Macrofauna I, Macrofauna II y ANH I; INVEMAR-ANH, 2008). Se usan con autorización, según lo informado por el docente; el texto de créditos debe confirmarse con la institución.
A5: Rasgos: Quimbayo, J.P., Silva, F.C., Mendes, T.C., Ferrari, D.S., Danielski, S.L., Bender, M.G., Parravicini, V., Kulbicki, M. y Floeter, S.R. (2021). Life-history traits, geographical range, and conservation aspects of reef fishes from the Atlantic and Eastern Pacific. Ecology, 102(5), e03298. doi:10.1002/ecy.3298. Datos: Zenodo, doi:10.5281/zenodo.4455016.
A7: 2. Hojas del libro
A8: Hoja | B8: Contenido
A9: tax | B9: Matriz sitios × especies (22 × 75): solo las especies con rasgos, en el mismo orden que la hoja rasgos. Sites1 es la región (N, M, S).
A10: rasgos | B10: Rasgos de las 75 especies de tax, con el diseño de la hoja rasgos del caso guiado (dieta con una sola categoría por especie).
A11: coord | B11: Coordenadas, estación original, campaña, año y profundidad de cada sitio, en el mismo orden que tax.
A12: amb | B12: Zonas, estrato de profundidad y variables ambientales de cada sitio, en el mismo orden que tax.
A13: rasgos_extra | B13: Rasgos adicionales de Quimbayo (categóricos y numéricos) de las mismas 75 especies; se unen por LatinName. Los vacíos son datos faltantes.
A14: tax_completa | B14: Matriz sitios × taxones (22 × 149) con todos los peces de estas estaciones, con y sin rasgos. Es la que corresponde a diversidad taxonómica.
A15: nombres | B15: Cruce de nombres: nombre original, nombre limpio, tipo y estado de los rasgos de cada taxón.
A17: 3. Cómo se construyó
A18: • Estaciones: las 22 con profundidad ≤ 100 m y datos biológicos. Todas son de la campaña Macrofauna II (2001). La estación E73 (89 m) figura en la hoja ambiental original, pero no tiene datos biológicos.
A19: • Peces: grupo «Peces» de la hoja Biol; se conservan los taxones con abundancia mayor que cero en estas estaciones.
A20: • Limpieza: se usa el código de estación E1–E96 como clave (en el archivo original, 8 códigos de la fila 2 de Biol traen un espacio inicial); se eliminaron espacios múltiples y finales en los nombres; no quedan columnas ni filas sin registros. La columna Cambio_de_nombre de la hoja nombres marca tanto las correcciones de espacios como las de ortografía.
A21: • Variantes ortográficas corregidas (mismo género, epíteto casi idéntico), pendientes de validar con una base taxonómica como WoRMS: Acanthostracion poligonius → Acanthostracion polygonius; Pristipomoides aquilionaris → Pristipomoides aquilonaris.
A22: • Zona: Zone1 es la columna Región del archivo original (N, M, S; el significado exacto de las letras está por confirmar). Depth_class es una regla propia: 20m (profundidad ≤ 50 m; 11 estaciones, 19.5–32.5 m) y 70m (> 50 m; 11 estaciones, 67–89 m).
A23: • Rasgos: tomados de Quimbayo et al. (2021) por coincidencia exacta del nombre científico, con la misma organización de la hoja rasgos de esa base para el curso (Guild traducida, dieta con una categoría por especie, BodyLengthMax en cm).
A25: 4. Advertencias
A26: • La hoja tax contiene solo las especies con rasgos. Los peces de estas estaciones sin rasgos (nombre no encontrado en Quimbayo o morfoespecie) están en tax_completa; analizar solo tax deja fuera casi la mitad de los individuos.
A27: • La dieta varía poco entre las especies de tax: la mayoría es invertívora (ver conteos abajo). Las categorías omnivory y herbivory tienen una o dos especies.
A28: • Los rasgos son a escala de especie y provienen de una base de peces arrecifales, mientras que los datos de abundancia son de capturas con red de arrastre demersal (dos arrastres de 10 min por sitio, según el protocolo del artículo). Cada sitio se muestreó una vez: las estaciones no son réplicas.
A29: • Las variables ambientales son estimaciones de modelos globales cercanas al fondo, según el artículo, y están muy correlacionadas con la profundidad; no son mediciones independientes por estación.
... A33: 5. Verificaciones y cifras (calculadas con fórmulas)
A34: Indicador | B34: Valor | C34: Nota
A35: Estaciones en tax | B35: =COUNTA(tax!A2:A23) -> 22
A36: Estaciones en coord y en amb | B36: =IF(AND(COUNTA(coord!A2:A23)=22,COUNTA(amb!A2:A23)=22),22,"revisar") -> 22 | C36: Mismo orden que tax.
A37: Especies en tax | B37: =COUNTA(tax!C1:BY1) -> 75
A38: Especies en rasgos | B38: =COUNTA(rasgos!B2:B76) -> 75
A39: tax y rasgos con las mismas especies | B39: =IF(COUNTA(tax!C1:BY1)=COUNTA(rasgos!B2:B76),"sí","no") -> sí | C39: Verificado también en el mismo orden.
A40: Taxones en tax_completa | B40: =COUNTA(tax_completa!C1:EU1) -> 149 | C40: Especies y morfoespecies.
A41: Individuos en tax | B41: =SUM(tax!C2:BY23) -> 1762
A42: Individuos en tax_completa | B42: =SUM(tax_completa!C2:EU23) -> 3323
A43: Individuos cubiertos con rasgos | B43: =B41/B42 -> 0.53024376 | C43: Proporción de tax respecto de tax_completa.
A44: Especies con rasgos (nombre exacto) | B44: =COUNTIF(nombres!D2:D150,"con rasgos (nombre exacto)") -> 73
A45: Especies con rasgos (variante corregida) | B45: =COUNTIF(nombres!D2:D150,"con rasgos (variante ortográfica corregida)") -> 2
A46: Especies sin rasgos (nombre no encontrado) | B46: =COUNTIF(nombres!D2:D150,"sin rasgos (nombre no encontrado en Quimbayo)") -> 61
A47: Morfoespecies sin rasgos | B47: =COUNTIF(nombres!D2:D150,"sin rasgos (morfoespecie)") -> 13
...
